<?xml version="1.0" encoding="utf-8"?>
<!-- This URDF was automatically created by SolidWorks to URDF Exporter! Originally created by Stephen Brawner (brawner@gmail.com) 
     Commit Version: 1.5.1-0-g916b5db  Build Version: 1.5.7152.31018
     For more information, please see http://wiki.ros.org/sw_urdf_exporter -->
<robot
  name="05144">
  <link
    name="Base">
    <inertial>
      <origin
        xyz="-0.142308649748716 0.108885138072049 0.0815546104060888"
        rpy="0 0 0" />
      <mass
        value="5.32485368404392" />
      <inertia
        ixx="0.0149047739356473"
        ixy="-1.47975231732828E-06"
        ixz="-7.80337094206553E-06"
        iyy="0.0219378727246539"
        iyz="-4.01751589933623E-06"
        izz="0.0232030208257597" />
    </inertial>
    <visual>
      <origin
        xyz="0 0 0"
        rpy="0 0 0" />
      <geometry>
        <mesh
          filename="package://05144/meshes/Base.STL" />
      </geometry>
      <material
        name="">
        <color
          rgba="0.752941176470588 0.752941176470588 0.752941176470588 1" />
      </material>
    </visual>
    <collision>
      <origin
        xyz="0 0 0"
        rpy="0 0 0" />
      <geometry>
        <mesh
          filename="package://05144/meshes/Base.STL" />
      </geometry>
    </collision>
  </link>
  <link
    name="LFS">
    <inertial>
      <origin
        xyz="0.0666875210853829 0.00348950989660696 -0.0643544912998069"
        rpy="0 0 0" />
      <mass
        value="0.26437001106022" />
      <inertia
        ixx="3.20746276473044E-05"
        ixy="-1.44118283518155E-07"
        ixz="-6.30853084354406E-08"
        iyy="6.22704126338821E-05"
        iyz="-2.01894652761254E-07"
        izz="6.28519936953906E-05" />
    </inertial>
    <visual>
      <origin
        xyz="0 0 0"
        rpy="0 0 0" />
      <geometry>
        <mesh
          filename="package://05144/meshes/LFS.STL" />
      </geometry>
      <material
        name="">
        <color
          rgba="0.752941176470588 0.752941176470588 0.752941176470588 1" />
      </material>
    </visual>
    <collision>
      <origin
        xyz="0 0 0"
        rpy="0 0 0" />
      <geometry>
        <mesh
          filename="package://05144/meshes/LFS.STL" />
      </geometry>
    </collision>
  </link>
  <joint
    name="LFS"
    type="prismatic">
    <origin
      xyz="-0.0508115623588095 0.315160991135077 -0.0467006291026886"
      rpy="2.8339623757072 0 -1.5707963267949" />
    <parent
      link="Base" />
    <child
      link="LFS" />
    <axis
      xyz="0 0.302801016091279 -0.953053799454201" />
    <limit
      lower="0"
      upper="0"
      effort="0"
      velocity="0" />
  </joint>
  <link
    name="LFW">
    <inertial>
      <origin
        xyz="-0.012315724574073 0 0"
        rpy="0 0 0" />
      <mass
        value="0.193585420779862" />
      <inertia
        ixx="0.000253081141332254"
        ixy="-5.88092833198904E-37"
        ixz="5.1845054750851E-21"
        iyy="0.000136818598566517"
        iyz="7.17557753438369E-37"
        izz="0.000136818598566517" />
    </inertial>
    <visual>
      <origin
        xyz="0 0 0"
        rpy="0 0 0" />
      <geometry>
        <mesh
          filename="package://05144/meshes/LFW.STL" />
      </geometry>
      <material
        name="">
        <color
          rgba="1 1 1 1" />
      </material>
    </visual>
    <collision>
      <origin
        xyz="0 0 0"
        rpy="0 0 0" />
      <geometry>
        <mesh
          filename="package://05144/meshes/LFW.STL" />
      </geometry>
    </collision>
  </link>
  <joint
    name="LFW"
    type="continuous">
    <origin
      xyz="0.000410991135076727 -0.0183719909934959 -0.0393036928458786"
      rpy="-1.87071350905913 0 3.14159265358979" />
    <parent
      link="LFS" />
    <child
      link="LFW" />
    <axis
      xyz="1 0 0" />
    <limit
      effort="3.1"
      velocity="7" />
  </joint>
  <link
    name="RFS">
    <inertial>
      <origin
        xyz="0.0724473276378515 -0.00248083053559417 -0.0665731861852051"
        rpy="0 0 0" />
      <mass
        value="0.264370011060221" />
      <inertia
        ixx="3.20746276473045E-05"
        ixy="1.44118283518171E-07"
        ixz="6.30853084354422E-08"
        iyy="6.22704126338823E-05"
        iyz="-2.01894652761264E-07"
        izz="6.28519936953909E-05" />
    </inertial>
    <visual>
      <origin
        xyz="0 0 0"
        rpy="0 0 0" />
      <geometry>
        <mesh
          filename="package://05144/meshes/RFS.STL" />
      </geometry>
      <material
        name="">
        <color
          rgba="0.752941176470588 0.752941176470588 0.752941176470588 1" />
      </material>
    </visual>
    <collision>
      <origin
        xyz="0 0 0"
        rpy="0 0 0" />
      <geometry>
        <mesh
          filename="package://05144/meshes/RFS.STL" />
      </geometry>
    </collision>
  </link>
  <joint
    name="RFS"
    type="prismatic">
    <origin
      xyz="-0.012128 -0.10492 -0.047016"
      rpy="2.834 0 1.5708" />
    <parent
      link="Base" />
    <child
      link="RFS" />
    <axis
      xyz="0 0.3028 -0.95305" />
    <limit
      lower="0"
      upper="0"
      effort="0"
      velocity="0" />
  </joint>
  <link
    name="RFW">
    <inertial>
      <origin
        xyz="-0.0123157245740731 0 1.38777878078145E-17"
        rpy="0 0 0" />
      <mass
        value="0.193585420779862" />
      <inertia
        ixx="0.000253081141332254"
        ixy="-1.23497249055924E-21"
        ixz="2.07163812308337E-21"
        iyy="0.000136818598566517"
        iyz="3.3881317890172E-21"
        izz="0.000136818598566517" />
    </inertial>
    <visual>
      <origin
        xyz="0 0 0"
        rpy="0 0 0" />
      <geometry>
        <mesh
          filename="package://05144/meshes/RFW.STL" />
      </geometry>
      <material
        name="">
        <color
          rgba="1 1 1 1" />
      </material>
    </visual>
    <collision>
      <origin
        xyz="0 0 0"
        rpy="0 0 0" />
      <geometry>
        <mesh
          filename="package://05144/meshes/RFW.STL" />
      </geometry>
    </collision>
  </link>
  <joint
    name="RFW"
    type="continuous">
    <origin
      xyz="0.0061708 0.00091629 -0.033508"
      rpy="-0.70714 0 3.1416" />
    <parent
      link="RFS" />
    <child
      link="RFW" />
    <axis
      xyz="1 0 0" />
    <limit
      effort="3.1"
      velocity="7" />
  </joint>
  <link
    name="LBS">
    <inertial>
      <origin
        xyz="0.0754022136877308 -0.00959516940601612 -0.0220143953841323"
        rpy="0 0 0" />
      <mass
        value="0.197009126147877" />
      <inertia
        ixx="1.68802738687173E-05"
        ixy="-1.14063956560669E-21"
        ixz="2.10922778942881E-20"
        iyy="5.0218488566757E-05"
        iyz="1.0508875929185E-06"
        izz="4.72447473350487E-05" />
    </inertial>
    <visual>
      <origin
        xyz="0 0 0"
        rpy="0 0 0" />
      <geometry>
        <mesh
          filename="package://05144/meshes/LBS.STL" />
      </geometry>
      <material
        name="">
        <color
          rgba="0.752941176470588 0.752941176470588 0.752941176470588 1" />
      </material>
    </visual>
    <collision>
      <origin
        xyz="0 0 0"
        rpy="0 0 0" />
      <geometry>
        <mesh
          filename="package://05144/meshes/LBS.STL" />
      </geometry>
    </collision>
  </link>
  <joint
    name="LBS"
    type="prismatic">
    <origin
      xyz="-0.23081 0.31516 0.0044202"
      rpy="2.834 0 -1.5708" />
    <parent
      link="Base" />
    <child
      link="LBS" />
    <axis
      xyz="0 0.3028 -0.95305" />
    <limit
      lower="0"
      upper="0"
      effort="0"
      velocity="0" />
  </joint>
  <link
    name="LBC">
    <inertial>
      <origin
        xyz="0.000464526735875104 -0.0102558391455497 0"
        rpy="0 0 0" />
      <mass
        value="0.043396245960262" />
      <inertia
        ixx="2.1180042472488E-05"
        ixy="5.53822046363834E-07"
        ixz="1.78671012311454E-22"
        iyy="1.76453344713605E-06"
        iyz="-2.2009621738811E-20"
        izz="2.14947085785555E-05" />
    </inertial>
    <visual>
      <origin
        xyz="0 0 0"
        rpy="0 0 0" />
      <geometry>
        <mesh
          filename="package://05144/meshes/LBC.STL" />
      </geometry>
      <material
        name="">
        <color
          rgba="0.898039215686275 0.917647058823529 0.929411764705882 1" />
      </material>
    </visual>
    <collision>
      <origin
        xyz="0 0 0"
        rpy="0 0 0" />
      <geometry>
        <mesh
          filename="package://05144/meshes/LBC.STL" />
      </geometry>
    </collision>
  </link>
  <joint
    name="LBC"
    type="continuous">
    <origin
      xyz="0.0411609911350767 -0.0150684419408271 -0.00478749419309586"
      rpy="-1.87842355251803 -0.00139263512405294 3.13720937469085" />
    <parent
      link="LBS" />
    <child
      link="LBC" />
    <axis
      xyz="0 1 0" />
  </joint>
  <link
    name="LBW">
    <inertial>
      <origin
        xyz="0.00647268691618069 1.38777878078145E-17 2.77555756156289E-17"
        rpy="0 0 0" />
      <mass
        value="0.0368891747697499" />
      <inertia
        ixx="1.67269024516251E-05"
        ixy="1.7292210705421E-21"
        ixz="-4.76786905075565E-21"
        iyy="8.8792623904253E-06"
        iyz="2.11758236813575E-22"
        izz="8.8792623904253E-06" />
    </inertial>
    <visual>
      <origin
        xyz="0 0 0"
        rpy="0 0 0" />
      <geometry>
        <mesh
          filename="package://05144/meshes/LBW.STL" />
      </geometry>
      <material
        name="">
        <color
          rgba="1 1 1 1" />
      </material>
    </visual>
    <collision>
      <origin
        xyz="0 0 0"
        rpy="0 0 0" />
      <geometry>
        <mesh
          filename="package://05144/meshes/LBW.STL" />
      </geometry>
    </collision>
  </link>
  <joint
    name="LBW"
    type="continuous">
    <origin
      xyz="0.00950064641853865 -0.037728919922878 0"
      rpy="-2.95846759930151 0 0" />
    <parent
      link="LBC" />
    <child
      link="LBW" />
    <axis
      xyz="1 0 0" />
    <limit
      effort="3.1"
      velocity="7" />
  </joint>
  <link
    name="RBS">
    <inertial>
      <origin
        xyz="0.0754022136877308 -0.00955739367510416 -0.0221332929503895"
        rpy="0 0 0" />
      <mass
        value="0.197009126147877" />
      <inertia
        ixx="1.68802738687173E-05"
        ixy="-2.46171681703945E-21"
        ixz="6.52693688329589E-22"
        iyy="5.0218488566757E-05"
        iyz="1.05088759291849E-06"
        izz="4.72447473350487E-05" />
    </inertial>
    <visual>
      <origin
        xyz="0 0 0"
        rpy="0 0 0" />
      <geometry>
        <mesh
          filename="package://05144/meshes/RBS.STL" />
      </geometry>
      <material
        name="">
        <color
          rgba="0.752941176470588 0.752941176470588 0.752941176470588 1" />
      </material>
    </visual>
    <collision>
      <origin
        xyz="0 0 0"
        rpy="0 0 0" />
      <geometry>
        <mesh
          filename="package://05144/meshes/RBS.STL" />
      </geometry>
    </collision>
  </link>
  <joint
    name="RBS"
    type="prismatic">
    <origin
      xyz="-0.19919 -0.099161 0.0042954"
      rpy="2.834 0 1.5708" />
    <parent
      link="Base" />
    <child
      link="RBS" />
    <axis
      xyz="0 0.3028 -0.95305" />
    <limit
      lower="0"
      upper="0"
      effort="0"
      velocity="0" />
  </joint>
  <link
    name="RBC">
    <inertial>
      <origin
        xyz="0.000464526735875104 -0.0101310848385787 2.77555756156289E-17"
        rpy="0 0 0" />
      <mass
        value="0.0433962459602619" />
      <inertia
        ixx="2.11800424724879E-05"
        ixy="5.53822046363849E-07"
        ixz="-4.64078919382898E-22"
        iyy="1.76453344713605E-06"
        iyz="2.0949176193518E-20"
        izz="2.14947085785555E-05" />
    </inertial>
    <visual>
      <origin
        xyz="0 0 0"
        rpy="0 0 0" />
      <geometry>
        <mesh
          filename="package://05144/meshes/RBC.STL" />
      </geometry>
      <material
        name="">
        <color
          rgba="0.898039215686275 0.917647058823529 0.929411764705882 1" />
      </material>
    </visual>
    <collision>
      <origin
        xyz="0 0 0"
        rpy="0 0 0" />
      <geometry>
        <mesh
          filename="package://05144/meshes/RBC.STL" />
      </geometry>
    </collision>
  </link>
  <joint
    name="RBC"
    type="continuous">
    <origin
      xyz="0.0411609911350767 -0.0150684419408278 -0.00478749419309604"
      rpy="-1.87842660467749 0 3.14159265358979" />
    <parent
      link="RBS" />
    <child
      link="RBC" />
    <axis
      xyz="0 1 0" />
  </joint>
  <link
    name="RBW">
    <inertial>
      <origin
        xyz="0.00647333333471939 -2.77555756156289E-17 1.38777878078145E-17"
        rpy="0 0 0" />
      <mass
        value="0.0368891747697499" />
      <inertia
        ixx="1.67269024516251E-05"
        ixy="-2.22678152353162E-21"
        ixz="-4.57890503447017E-22"
        iyy="8.87926239042531E-06"
        iyz="0"
        izz="8.8792623904253E-06" />
    </inertial>
    <visual>
      <origin
        xyz="0 0 0"
        rpy="0 0 0" />
      <geometry>
        <mesh
          filename="package://05144/meshes/RBW.STL" />
      </geometry>
      <material
        name="">
        <color
          rgba="1 1 1 1" />
      </material>
    </visual>
    <collision>
      <origin
        xyz="0 0 0"
        rpy="0 0 0" />
      <geometry>
        <mesh
          filename="package://05144/meshes/RBW.STL" />
      </geometry>
    </collision>
  </link>
  <joint
    name="RBW"
    type="continuous">
    <origin
      xyz="0.00949999999999995 -0.0376041656159069 0"
      rpy="0.983654154638768 0 0" />
    <parent
      link="RBC" />
    <child
      link="RBW" />
    <axis
      xyz="1 0 0" />
    <limit
      effort="3.1"
      velocity="7" />
  </joint>
  <link
    name="Lidar">
    <inertial>
      <origin
        xyz="-0.0784930236720806 0.744427434110801 0.133449662205116"
        rpy="0 0 0" />
      <mass
        value="0.0730845741838002" />
      <inertia
        ixx="1.9580876083019E-05"
        ixy="-4.28391161226819E-07"
        ixz="1.03933621130234E-07"
        iyy="4.14184522502777E-05"
        iyz="-9.42743593249038E-09"
        izz="2.41250083307634E-05" />
    </inertial>
    <visual>
      <origin
        xyz="0 0 0"
        rpy="0 0 0" />
      <geometry>
        <mesh
          filename="package://05144/meshes/Lidar.STL" />
      </geometry>
      <material
        name="">
        <color
          rgba="0.792156862745098 0.819607843137255 0.933333333333333 1" />
      </material>
    </visual>
    <collision>
      <origin
        xyz="0 0 0"
        rpy="0 0 0" />
      <geometry>
        <mesh
          filename="package://05144/meshes/Lidar.STL" />
      </geometry>
    </collision>
  </link>
  <joint
    name="Lidar"
    type="fixed">
    <origin
      xyz="-0.098561 0.24092 -0.5487"
      rpy="1.5708 0 0" />
    <parent
      link="Base" />
    <child
      link="Lidar" />
    <axis
      xyz="0 0 0" />
  </joint>
  <link
    name="Front_Cam">
    <inertial>
      <origin
        xyz="0.0498359970771496 0.061783635914709 0.0687226592339399"
        rpy="0 0 0" />
      <mass
        value="0.0436119948521297" />
      <inertia
        ixx="4.2947913749771E-06"
        ixy="-8.85886294504935E-10"
        ixz="-1.01812872210218E-09"
        iyy="2.21058139310684E-05"
        iyz="2.17578140553955E-08"
        izz="2.35707056576044E-05" />
    </inertial>
    <visual>
      <origin
        xyz="0 0 0"
        rpy="0 0 0" />
      <geometry>
        <mesh
          filename="package://05144/meshes/Front_Cam.STL" />
      </geometry>
      <material
        name="">
        <color
          rgba="0.792156862745098 0.819607843137255 0.933333333333333 1" />
      </material>
    </visual>
    <collision>
      <origin
        xyz="0 0 0"
        rpy="0 0 0" />
      <geometry>
        <mesh
          filename="package://05144/meshes/Front_Cam.STL" />
      </geometry>
    </collision>
  </link>
  <joint
    name="Front_Cam"
    type="fixed">
    <origin
      xyz="-0.080278 0.058161 0.092502"
      rpy="1.5708 0 1.5708" />
    <parent
      link="Base" />
    <child
      link="Front_Cam" />
    <axis
      xyz="0 0 0" />
  </joint>
  <link
    name="Ball_cam">
    <inertial>
      <origin
        xyz="0.0498359969056821 0.0617836349793441 0.068722659562668"
        rpy="0 0 0" />
      <mass
        value="0.043611995173567" />
      <inertia
        ixx="4.29479052042009E-06"
        ixy="-8.85250523894349E-10"
        ixz="-1.01843894196781E-09"
        iyy="2.21058148306724E-05"
        iyz="2.17581061750722E-08"
        izz="2.35707057120248E-05" />
    </inertial>
    <visual>
      <origin
        xyz="0 0 0"
        rpy="0 0 0" />
      <geometry>
        <mesh
          filename="package://05144/meshes/Ball_cam.STL" />
      </geometry>
      <material
        name="">
        <color
          rgba="0.792156862745098 0.819607843137255 0.933333333333333 1" />
      </material>
    </visual>
    <collision>
      <origin
        xyz="0 0 0"
        rpy="0 0 0" />
      <geometry>
        <mesh
          filename="package://05144/meshes/Ball_cam.STL" />
      </geometry>
    </collision>
  </link>
  <joint
    name="Ball_cam"
    type="fixed">
    <origin
      xyz="-0.101690797714348 0.0579934881168203 0.10583711644311"
      rpy="2.20211757959882 0 1.5707963267949" />
    <parent
      link="Base" />
    <child
      link="Ball_cam" />
    <axis
      xyz="0 0 0" />
  </joint>
</robot>